Failure # 1 (occurred at 2024-07-02_15-57-12)
Traceback (most recent call last):
  File "C:\Users\28420\AppData\Roaming\Python\Python38\site-packages\ray\tune\trial_runner.py", line 886, in _process_trial
    results = self.trial_executor.fetch_result(trial)
  File "C:\Users\28420\AppData\Roaming\Python\Python38\site-packages\ray\tune\ray_trial_executor.py", line 675, in fetch_result
    result = ray.get(trial_future[0], timeout=DEFAULT_GET_TIMEOUT)
  File "C:\Users\28420\AppData\Roaming\Python\Python38\site-packages\ray\_private\client_mode_hook.py", line 105, in wrapper
    return func(*args, **kwargs)
  File "C:\Users\28420\AppData\Roaming\Python\Python38\site-packages\ray\worker.py", line 1765, in get
    raise value
ray.exceptions.RayActorError: The actor died because of an error raised in its creation task, [36mray::PPOTrainer.__init__()[39m (pid=3380, ip=127.0.0.1, repr=PPOTrainer)
  File "C:\Users\28420\AppData\Roaming\Python\Python38\site-packages\ray\util\tracing\tracing_helper.py", line 451, in _resume_span
    return method(self, *_args, **_kwargs)
  File "C:\Users\28420\AppData\Roaming\Python\Python38\site-packages\ray\rllib\agents\trainer.py", line 925, in _init
    raise NotImplementedError
NotImplementedError

During handling of the above exception, another exception occurred:

[36mray::PPOTrainer.__init__()[39m (pid=3380, ip=127.0.0.1, repr=PPOTrainer)
  File "python\ray\_raylet.pyx", line 633, in ray._raylet.execute_task
  File "python\ray\_raylet.pyx", line 674, in ray._raylet.execute_task
  File "python\ray\_raylet.pyx", line 640, in ray._raylet.execute_task
  File "python\ray\_raylet.pyx", line 644, in ray._raylet.execute_task
  File "python\ray\_raylet.pyx", line 593, in ray._raylet.execute_task.function_executor
  File "C:\Users\28420\AppData\Roaming\Python\Python38\site-packages\ray\_private\function_manager.py", line 648, in actor_method_executor
    return method(__ray_actor, *args, **kwargs)
  File "C:\Users\28420\AppData\Roaming\Python\Python38\site-packages\ray\util\tracing\tracing_helper.py", line 451, in _resume_span
    return method(self, *_args, **_kwargs)
  File "C:\Users\28420\AppData\Roaming\Python\Python38\site-packages\ray\rllib\agents\trainer.py", line 746, in __init__
    super().__init__(config, logger_creator, remote_checkpoint_dir,
  File "C:\Users\28420\AppData\Roaming\Python\Python38\site-packages\ray\tune\trainable.py", line 124, in __init__
    self.setup(copy.deepcopy(self.config))
  File "C:\Users\28420\AppData\Roaming\Python\Python38\site-packages\ray\util\tracing\tracing_helper.py", line 451, in _resume_span
    return method(self, *_args, **_kwargs)
  File "C:\Users\28420\AppData\Roaming\Python\Python38\site-packages\ray\rllib\agents\trainer.py", line 822, in setup
    self.workers = self._make_workers(
  File "C:\Users\28420\AppData\Roaming\Python\Python38\site-packages\ray\util\tracing\tracing_helper.py", line 451, in _resume_span
    return method(self, *_args, **_kwargs)
  File "C:\Users\28420\AppData\Roaming\Python\Python38\site-packages\ray\rllib\agents\trainer.py", line 1995, in _make_workers
    return WorkerSet(
  File "C:\Users\28420\AppData\Roaming\Python\Python38\site-packages\ray\rllib\evaluation\worker_set.py", line 101, in __init__
    remote_spaces = ray.get(self.remote_workers(
  File "C:\Users\28420\AppData\Roaming\Python\Python38\site-packages\ray\_private\client_mode_hook.py", line 105, in wrapper
    return func(*args, **kwargs)
  File "C:\Users\28420\AppData\Roaming\Python\Python38\site-packages\ray\worker.py", line 1765, in get
    raise value
ray.exceptions.RayActorError: The actor died because of an error raised in its creation task, [36mray::RolloutWorker.__init__()[39m (pid=3080, ip=127.0.0.1, repr=<ray.rllib.evaluation.rollout_worker.RolloutWorker object at 0x0000017969547910>)
  File "python\ray\_raylet.pyx", line 640, in ray._raylet.execute_task
  File "python\ray\_raylet.pyx", line 644, in ray._raylet.execute_task
  File "python\ray\_raylet.pyx", line 593, in ray._raylet.execute_task.function_executor
  File "C:\Users\28420\AppData\Roaming\Python\Python38\site-packages\ray\_private\function_manager.py", line 648, in actor_method_executor
    return method(__ray_actor, *args, **kwargs)
  File "C:\Users\28420\AppData\Roaming\Python\Python38\site-packages\ray\util\tracing\tracing_helper.py", line 451, in _resume_span
    return method(self, *_args, **_kwargs)
  File "C:\Users\28420\AppData\Roaming\Python\Python38\site-packages\ray\rllib\evaluation\rollout_worker.py", line 462, in __init__
    _validate_env(self.env, env_context=self.env_context)
  File "C:\Users\28420\AppData\Roaming\Python\Python38\site-packages\ray\rllib\evaluation\rollout_worker.py", line 1724, in _validate_env
    raise EnvError(
ray.rllib.utils.error.EnvError: Env's `observation_space` Box([[-200. -200. -200. -200. -200. -200.]
 [-200. -200. -200. -200. -200. -200.]
 [-200. -200. -200. -200. -200. -200.]
 [-200. -200. -200. -200. -200. -200.]
 [-200. -200. -200. -200. -200. -200.]
 [-200. -200. -200. -200. -200. -200.]], [[200. 200. 200. 200. 200. 200.]
 [200. 200. 200. 200. 200. 200.]
 [200. 200. 200. 200. 200. 200.]
 [200. 200. 200. 200. 200. 200.]
 [200. 200. 200. 200. 200. 200.]
 [200. 200. 200. 200. 200. 200.]], (6, 6), float32) does not contain returned observation after a reset ([[ 26.378092   0.        90.         0.       174.00735    1.      ]
 [ 26.357931   0.        90.       113.       179.44713    1.      ]
 [  0.         0.         0.         0.         0.         0.      ]
 [ 24.6535     0.        90.        31.       179.50418    0.      ]
 [ 36.702847   0.        90.        63.       106.01208    1.      ]
 [  0.         0.         0.         0.         0.         0.      ]
 [ 24.581287   0.        90.        29.       140.08226    0.      ]])!

